<?xml version="1.0"?>
<robot name="dodo_robot">
  
  <material name="white">
      <color rgba="1 1 1 1" />
  </material>

  <material name="grey">
      <color rgba="0.5 0.5 0.5 1" />
  </material>

  <material name="black">
      <color rgba="0 0 0 1" />
  </material>



  <link name="base_link">
    <collision>
        <geometry>
          <box size="0.6 0.6 0.1033252"/>
        </geometry>
      <material name="balck"/>
    </collision>
    <inertial>
      <mass value="10"/>
      <inertia ixx="0.01" iyy="0.01" izz="0.01" ixy="0" ixz="0" iyz="0"/>
    </inertial>
    <visual>
      <geometry>
        <box size=" 0.6 0.6 0.1033252"/>
      </geometry>
      <material name="grey"/>
    </visual>
  </link>

 
    <link name="right_front_wheel">
    <collision>
        <geometry>
          <cylinder length="0.039" radius="0.065"/>
        </geometry>
        <origin rpy="0 1.5708 0" xyz="0 0 0"/>
      <material name="balck"/>
    </collision>
    <inertial>
      <mass value="1"/>
      <inertia ixx="0.001" iyy="0.001" izz="0.001" ixy="0" ixz="0" iyz="0"/>
    </inertial>
    <visual>
      <geometry>
        <cylinder length="0.039" radius="0.0635"/>
      </geometry>
      <material name="black"/>
      <origin rpy="0 1.5708 0" xyz="0 0 0"/>
    </visual>
  </link>

  <joint name="base_to_right_front_wheel" type="continuous">
    <parent link="base_link"/>
    <child link="right_front_wheel"/>
    <origin rpy="0 0 0.785398" xyz="0.3 0.3  0"/>
  </joint>
  
  <link name="left_front_wheel">
    <collision>
        <geometry>
          <cylinder length="0.039" radius="0.0635"/>
        </geometry>
        <origin rpy="0 1.5708 0" xyz="0 0 0"/>
      <material name="balck"/>
    </collision>
    <inertial>
      <mass value="1"/>
      <inertia ixx="0.001" iyy="0.001" izz="0.001" ixy="0" ixz="0" iyz="0"/>
    </inertial>
    <visual>
      <geometry>
        <cylinder length="0.039" radius="0.0635"/>
      </geometry>
      <material name="black"/>
      <origin rpy="0 1.5708 0" xyz="0 0 0"/>
    </visual>
  </link>

  <joint name="base_to_left_front_wheel" type="continuous">
    <parent link="base_link"/>
    <child link="left_front_wheel"/>
    <origin rpy="0 0 2.35619" xyz="-0.3 0.3  0"/>
  </joint>

  <link name="left_back_wheel">
    <collision>
        <geometry>
          <cylinder length="0.039" radius="0.0635"/>
        </geometry>
      <material name="balck"/>
    </collision>
    <inertial>
      <mass value="1"/>
      <inertia ixx="0.001" iyy="0.001" izz="0.001" ixy="0" ixz="0" iyz="0"/>
    </inertial>
    <visual>
      <geometry>
        <cylinder length="0.039" radius="0.0635"/>
      </geometry>
      <material name="black"/>
      <origin rpy="0 1.5708 0" xyz="0 0 0"/>
    </visual>
  </link>

  <joint name="base_to_left_back_wheel" type="continuous">
    <parent link="base_link"/>
    <child link="left_back_wheel"/>
    <origin rpy="0 0 0.785398" xyz="-0.3 -0.3  0"/>
  </joint>

  <link name="right_back_wheel">
    <collision>
        <geometry>
          <cylinder length="0.039" radius="0.0635"/>
        </geometry>
        <origin rpy="0 1.5708 0" xyz="0 0 0"/>
      <material name="balck"/>
    </collision>
    <inertial>
      <mass value="1"/>
      <inertia ixx="0.001" iyy="0.001" izz="0.001" ixy="0" ixz="0" iyz="0"/>
    </inertial>
    <visual>
      <geometry>
        <cylinder length="0.039" radius="0.0635"/>
      </geometry>
      <material name="black"/>
      <origin rpy="0 1.5708 0" xyz="0 0 0"/>
    </visual>
  </link>

  <joint name="base_to_right_back_wheel" type="continuous">
    <parent link="base_link"/>
    <child link="right_back_wheel"/>
    <origin rpy="0 0 2.35619" xyz="0.3 -0.3  0"/>
  </joint>
  <gazebo>
        <plugin name="omni_steering" filename="libgazebo_ros_planar_move.so">
            <commandTopic>cmd_vel</commandTopic>
            <odometryTopic>odom</odometryTopic>
            <odometryFrame>odom</odometryFrame>
            <odometryRate>50.0</odometryRate>
            <robotBaseFrame>base_link</robotBaseFrame>
            <publishTF>false</publishTF>
        </plugin>
    </gazebo>

  
</robot>

